<?xml version="1.0"?>
<robot name="letter_writer_4dof">

  <!-- Base Link (fixed to ground) -->
  <link name="base_link">
    <visual>
      <geometry>
        <cylinder radius="0.03" length="0.45"/>
      </geometry>
      <origin xyz="0 0 0.225" rpy="0 0 0"/>
    </visual>
    <inertial>
      <mass value="4.0"/>
      <origin xyz="0 0 0.225" rpy="0 0 0"/>
      <inertia ixx="0.703" iyy="0.706" izz="0.009" ixy="0" ixz="0" iyz="0"/>
    </inertial>
  </link>

  <!-- Joint 1: Base Rotation (Revolute - Rz) -->
  <joint name="base_joint" type="revolute">
    <parent link="base_link"/>
    <child link="shoulder_base_link"/>
    <origin xyz="0 0 0.45" rpy="0 0 0"/>
    <axis xyz="0 0 1"/>
    <limit lower="-3.14" upper="3.14" effort="100.0" velocity="2.0"/>
  </joint>

  <!-- Shoulder Base Link (before prismatic extension) -->
  <link name="shoulder_base_link">
    <!-- Outer cylinder (static) -->
    <visual>
      <geometry>
        <cylinder radius="0.025" length="0.1"/>
      </geometry>
      <origin xyz="0.05 0 0" rpy="0 1.5708 0"/>
    </visual>
    <inertial>
      <mass value="1.5"/>
      <origin xyz="0.05 0 0" rpy="0 0 0"/>
      <inertia ixx="0.013" iyy="0.013" izz="0.0005" ixy="0" ixz="0" iyz="0"/>
    </inertial>
  </link>

  <!-- Joint 2: Shoulder Extension (Prismatic - extends along X) -->
  <joint name="shoulder_extend_joint" type="prismatic">
    <parent link="shoulder_base_link"/>
    <child link="shoulder_link"/>
    <origin xyz="0.1 0 0" rpy="0 0 0"/>
    <axis xyz="1 0 0"/>
    <limit lower="0.0" upper="0.5" effort="50.0" velocity="0.5"/>
  </joint>

  <!-- Shoulder Link (after prismatic extension) -->
  <link name="shoulder_link">
    <!-- Extending rod that connects back to parent -->
    <!-- This rod extends backwards from origin to always connect with parent -->
    <!-- Length is 0.6m to cover max extension of 0.5m plus overlap -->
    <visual>
      <geometry>
        <cylinder radius="0.018" length="0.6"/>
      </geometry>
      <origin xyz="-0.3 0 0" rpy="0 1.5708 0"/>
    </visual>
    <!-- Connection sphere at start of main arm -->
    <visual>
      <geometry>
        <sphere radius="0.02"/>
      </geometry>
      <origin xyz="0 0 0" rpy="0 0 0"/>
    </visual>
    <!-- Main shoulder extension along X (reduced to 0.2m) -->
    <visual>
      <geometry>
        <box size="0.2 0.02 0.02"/>
      </geometry>
      <origin xyz="0.1 0 0" rpy="0 0 0"/>
    </visual>
    <!-- Junction sphere at bend point -->
    <visual>
      <geometry>
        <sphere radius="0.02"/>
      </geometry>
      <origin xyz="0.2 0 0" rpy="0 0 0"/>
    </visual>
    <!-- Offset connector perpendicular in +Y direction (from (0.2,0,0) to (0.2,0.08,0)) -->
    <visual>
      <geometry>
        <box size="0.02 0.08 0.02"/>
      </geometry>
      <origin xyz="0.2 0.04 0" rpy="0 0 0"/>
    </visual>
    <!-- Junction sphere at elbow joint -->
    <visual>
      <geometry>
        <sphere radius="0.02"/>
      </geometry>
      <origin xyz="0.2 0.08 0" rpy="0 0 0"/>
    </visual>
    <inertial>
      <mass value="2.0"/>
      <origin xyz="0.1 0 0" rpy="0 0 0"/>
      <inertia ixx="0.15" iyy="0.15" izz="0.0008" ixy="0" ixz="0" iyz="0"/>
    </inertial>
  </link>

  <!-- Joint 3: Elbow Pitch (Revolute) with OFFSET -->
  <joint name="elbow_joint" type="revolute">
    <parent link="shoulder_link"/>
    <child link="elbow_link"/>
    <origin xyz="0.2 0.08 0" rpy="1.5708 0 0"/>
    <axis xyz="0 0 1"/>
    <limit lower="-1.57" upper="1.57" effort="40.0" velocity="2.0"/>
  </joint>

  <!-- Elbow Link (reduced to 0.25m) -->
  <link name="elbow_link">
    <visual>
      <geometry>
        <cylinder radius="0.015" length="0.25"/>
      </geometry>
      <!-- After rpy rotation in joint, local X goes along parent's Y -->
      <!-- So this cylinder along X in rotated frame = along Y in parent frame -->
      <origin xyz="0.125 0 0" rpy="0 1.5708 0"/>
    </visual>
    <inertial>
      <mass value="1.8"/>
      <origin xyz="0.125 0 0" rpy="0 0 0"/>
      <inertia ixx="0.18" iyy="0.18" izz="0.0004" ixy="0" ixz="0" iyz="0"/>
    </inertial>
  </link>

  <!-- Joint 4: Wrist Pitch (Revolute - Ry) -->
  <joint name="wrist_joint" type="revolute">
    <parent link="elbow_link"/>
    <child link="wrist_link"/>
    <origin xyz="0.25 0 0" rpy="0 0 0"/>
    <axis xyz="0 1 0"/>
    <limit lower="-2.09" upper="0.35" effort="20.0" velocity="2.0"/>
  </joint>

  <!-- Wrist Link (reduced to 0.12m) -->
  <link name="wrist_link">
    <visual>
      <geometry>
        <cylinder radius="0.01" length="0.12"/>
      </geometry>
      <origin xyz="0.06 0 0" rpy="0 1.5708 0"/>
    </visual>
    <inertial>
      <mass value="1.0"/>
      <origin xyz="0.06 0 0" rpy="0 0 0"/>
      <inertia ixx="0.019" iyy="0.019" izz="0.00005" ixy="0" ixz="0" iyz="0"/>
    </inertial>
  </link>

  <!-- End Effector (Pen) -->
  <link name="end_effector">
    <visual>
      <geometry>
        <sphere radius="0.01"/>
      </geometry>
      <origin xyz="0 0 0" rpy="0 0 0"/>
    </visual>
    <inertial>
      <mass value="0.07"/>
      <origin xyz="0 0 0" rpy="0 0 0"/>
      <inertia ixx="0.00001" iyy="0.00001" izz="0.00001" ixy="0" ixz="0" iyz="0"/>
    </inertial>
  </link>

  <!-- Fixed joint to attach end effector -->
  <joint name="end_effector_joint" type="fixed">
    <parent link="wrist_link"/>
    <child link="end_effector"/>
    <origin xyz="0.15 0 0" rpy="0 0 0"/>
  </joint>

</robot>
