<?xml version="1.0"?>
<robot name="letter_writer_4dof">

  <!-- Base Link (fixed to ground) -->
  <link name="base_link">
    <visual>
      <geometry>
        <cylinder radius="0.03" length="0.45"/>
      </geometry>
      <origin xyz="0 0 0.225" rpy="0 0 0"/>
    </visual>
    <inertial>
      <mass value="4.0"/>
      <origin xyz="0 0 0.225" rpy="0 0 0"/>
      <inertia ixx="0.703" iyy="0.706" izz="0.009" ixy="0" ixz="0" iyz="0"/>
    </inertial>
  </link>

  <!-- Joint 1: Base Rotation (Revolute - Rz) -->
  <joint name="base_joint" type="revolute">
    <parent link="base_link"/>
    <child link="shoulder_link"/>
    <origin xyz="0 0 0.45" rpy="0 0 0"/>
    <axis xyz="0 0 1"/>
    <limit lower="-3.14" upper="3.14" effort="100.0" velocity="2.0"/>
  </joint>

  <!-- Shoulder Link -->
  <link name="shoulder_link">
    <visual>
      <geometry>
        <cylinder radius="0.02" length="0.3"/>
      </geometry>
      <origin xyz="0.15 0 0" rpy="0 1.5708 0"/>
    </visual>
    <inertial>
      <mass value="2.8"/>
      <origin xyz="0.15 0 0" rpy="0 0 0"/>
      <inertia ixx="0.21" iyy="0.21" izz="0.0011" ixy="0" ixz="0" iyz="0"/>
    </inertial>
  </link>

  <!-- Joint 2: Shoulder Pitch (Revolute - Ry) -->
  <joint name="shoulder_joint" type="revolute">
    <parent link="shoulder_link"/>
    <child link="elbow_link"/>
    <origin xyz="0.3 0 0" rpy="0 0 0"/>
    <axis xyz="0 1 0"/>
    <limit lower="-1.57" upper="1.57" effort="50.0" velocity="2.0"/>
  </joint>

  <!-- Elbow Link -->
  <link name="elbow_link">
    <visual>
      <geometry>
        <cylinder radius="0.015" length="0.35"/>
      </geometry>
      <origin xyz="0.175 0 0" rpy="0 1.5708 0"/>
    </visual>
    <inertial>
      <mass value="2.1"/>
      <origin xyz="0.175 0 0" rpy="0 0 0"/>
      <inertia ixx="0.215" iyy="0.215" izz="0.0005" ixy="0" ixz="0" iyz="0"/>
    </inertial>
  </link>

  <!-- Joint 3: Elbow Pitch (Revolute - Ry) -->
  <joint name="elbow_joint" type="revolute">
    <parent link="elbow_link"/>
    <child link="wrist_link"/>
    <origin xyz="0.35 0 0" rpy="0 0 0"/>
    <axis xyz="0 1 0"/>
    <limit lower="-2.09" upper="0.35" effort="40.0" velocity="2.0"/>
  </joint>

  <!-- Wrist Link (Prismatic Base) -->
  <link name="wrist_link">
    <visual>
      <geometry>
        <cylinder radius="0.01" length="0.1"/>
      </geometry>
      <origin xyz="0.05 0 0" rpy="0 1.5708 0"/>
    </visual>
    <inertial>
      <mass value="1.3"/>
      <origin xyz="0.05 0 0" rpy="0 0 0"/>
      <inertia ixx="0.001" iyy="0.001" izz="0.00007" ixy="0" ixz="0" iyz="0"/>
    </inertial>
  </link>

  <!-- Joint 4: Wrist Extension (Prismatic) -->
  <joint name="wrist_extend_joint" type="prismatic">
    <parent link="wrist_link"/>
    <child link="end_effector"/>
    <origin xyz="0.1 0 0" rpy="0 0 0"/>
    <axis xyz="1 0 0"/>
    <limit lower="0.0" upper="1.0" effort="20.0" velocity="0.5"/>
  </joint>

  <!-- End Effector (Pen) -->
  <link name="end_effector">
    <visual>
      <geometry>
        <sphere radius="0.01"/>
      </geometry>
      <origin xyz="0 0 0" rpy="0 0 0"/>
    </visual>
    <inertial>
      <mass value="0.07"/>
      <origin xyz="0 0 0" rpy="0 0 0"/>
      <inertia ixx="0.00001" iyy="0.00001" izz="0.00001" ixy="0" ixz="0" iyz="0"/>
    </inertial>
  </link>

</robot>
